2020-05-05 19:35:48,085 INFO: Microblog startup [in C:\Users\Администратор\Documents\web_app\app\__init__.py:43]
2020-05-05 19:38:15,402 INFO: Microblog startup [in C:\Users\Администратор\Documents\web_app\app\__init__.py:43]
2020-05-05 19:43:58,718 INFO: Microblog startup [in C:\Users\Администратор\Documents\web_app\app\__init__.py:43]
2020-05-05 19:44:09,669 INFO: Microblog startup [in C:\Users\Администратор\Documents\web_app\app\__init__.py:43]
2020-05-05 20:04:24,474 INFO: Microblog startup [in C:\Users\Администратор\Documents\web_app\app\__init__.py:43]
2020-05-07 00:19:05,414 INFO: Microblog startup [in C:\Users\Администратор\Documents\web_app\app\__init__.py:43]
2020-05-07 00:23:40,188 INFO: Microblog startup [in C:\Users\Администратор\Documents\web_app\app\__init__.py:43]
2020-05-07 00:42:57,279 INFO: Microblog startup [in C:\Users\Администратор\Documents\web_app\app\__init__.py:43]
2020-05-07 00:43:21,824 INFO: Microblog startup [in C:\Users\Администратор\Documents\web_app\app\__init__.py:43]
2020-05-07 00:43:55,700 INFO: Microblog startup [in C:\Users\Администратор\Documents\web_app\app\__init__.py:43]
2020-05-07 17:30:54,488 INFO: Microblog startup [in C:\Users\Администратор\Documents\web_app\app\__init__.py:43]
2020-05-13 18:27:36,827 INFO: Microblog startup [in C:\Users\Администратор\Documents\web_app\app\__init__.py:45]
2020-05-13 18:30:38,797 INFO: Microblog startup [in C:\Users\Администратор\Documents\web_app\app\__init__.py:45]
2020-05-13 18:31:36,843 INFO: Microblog startup [in C:\Users\Администратор\Documents\web_app\app\__init__.py:45]
2020-05-13 18:34:19,959 INFO: Microblog startup [in C:\Users\Администратор\Documents\web_app\app\__init__.py:45]
2020-05-13 18:44:49,987 INFO: Microblog startup [in C:\Users\Администратор\Documents\web_app\app\__init__.py:47]
2020-05-13 18:46:03,315 INFO: Microblog startup [in C:\Users\Администратор\Documents\web_app\app\__init__.py:47]
2020-05-13 18:49:47,145 INFO: Microblog startup [in C:\Users\Администратор\Documents\web_app\app\__init__.py:47]
2020-05-13 23:21:48,540 INFO: Microblog startup [in C:\Users\Администратор\Documents\web_app\app\__init__.py:47]
2020-05-14 00:24:45,158 INFO: Microblog startup [in C:\Users\Администратор\Documents\web_app\app\__init__.py:47]
2020-05-25 15:37:59,517 INFO: Microblog startup [in C:\Users\Администратор\Documents\web_app\app\__init__.py:47]
2020-05-25 15:38:20,668 ERROR: Exception on / [GET] [in c:\programdata\anaconda3\lib\site-packages\flask\app.py:1892]
Traceback (most recent call last):
  File "c:\programdata\anaconda3\lib\site-packages\sqlalchemy\engine\base.py", line 1246, in _execute_context
    cursor, statement, parameters, context
  File "c:\programdata\anaconda3\lib\site-packages\sqlalchemy\engine\default.py", line 588, in do_execute
    cursor.execute(statement, parameters)
sqlite3.OperationalError: no such table: post_like

The above exception was the direct cause of the following exception:

Traceback (most recent call last):
  File "c:\programdata\anaconda3\lib\site-packages\flask\app.py", line 2447, in wsgi_app
    response = self.full_dispatch_request()
  File "c:\programdata\anaconda3\lib\site-packages\flask\app.py", line 1952, in full_dispatch_request
    rv = self.handle_user_exception(e)
  File "c:\programdata\anaconda3\lib\site-packages\flask\app.py", line 1821, in handle_user_exception
    reraise(exc_type, exc_value, tb)
  File "c:\programdata\anaconda3\lib\site-packages\flask\_compat.py", line 39, in reraise
    raise value
  File "c:\programdata\anaconda3\lib\site-packages\flask\app.py", line 1950, in full_dispatch_request
    rv = self.dispatch_request()
  File "c:\programdata\anaconda3\lib\site-packages\flask\app.py", line 1936, in dispatch_request
    return self.view_functions[rule.endpoint](**req.view_args)
  File "c:\programdata\anaconda3\lib\site-packages\flask_login\utils.py", line 272, in decorated_view
    return func(*args, **kwargs)
  File "C:\Users\Администратор\Documents\web_app\app\routes.py", line 36, in index
    prev_url=prev_url)
  File "c:\programdata\anaconda3\lib\site-packages\flask\templating.py", line 140, in render_template
    ctx.app,
  File "c:\programdata\anaconda3\lib\site-packages\flask\templating.py", line 120, in _render
    rv = template.render(context)
  File "c:\programdata\anaconda3\lib\site-packages\jinja2\environment.py", line 1090, in render
    self.environment.handle_exception()
  File "c:\programdata\anaconda3\lib\site-packages\jinja2\environment.py", line 832, in handle_exception
    reraise(*rewrite_traceback_stack(source=source))
  File "c:\programdata\anaconda3\lib\site-packages\jinja2\_compat.py", line 28, in reraise
    raise value.with_traceback(tb)
  File "C:\Users\Администратор\Documents\web_app\app\templates\index.html", line 1, in top-level template code
    {% extends "base.html" %}
  File "C:\Users\Администратор\Documents\web_app\app\templates\base.html", line 1, in top-level template code
    {% extends 'bootstrap/base.html' %}
  File "c:\programdata\anaconda3\lib\site-packages\flask_bootstrap\templates\bootstrap\base.html", line 1, in top-level template code
    {% block doc -%}
  File "c:\programdata\anaconda3\lib\site-packages\flask_bootstrap\templates\bootstrap\base.html", line 3, in block "doc"
    <html{% block html_attribs %}{% endblock html_attribs %}>
  File "c:\programdata\anaconda3\lib\site-packages\flask_bootstrap\templates\bootstrap\base.html", line 11, in block "html"
    {%- endblock metas %}
  File "c:\programdata\anaconda3\lib\site-packages\flask_bootstrap\templates\bootstrap\base.html", line 13, in block "body"
    {%- block styles %}
  File "C:\Users\Администратор\Documents\web_app\app\templates\index.html", line 19, in block "content"
    {% include '_post.html' %}
  File "C:\Users\Администратор\Documents\web_app\app\templates\_post.html", line 16, in top-level template code
    {% if current_user.has_liked_post(post) %}
  File "C:\Users\Администратор\Documents\web_app\app\models.py", line 84, in has_liked_post
    PostLike.post_id == post.id).count() > 0
  File "c:\programdata\anaconda3\lib\site-packages\sqlalchemy\orm\query.py", line 3653, in count
    return self.from_self(col).scalar()
  File "c:\programdata\anaconda3\lib\site-packages\sqlalchemy\orm\query.py", line 3377, in scalar
    ret = self.one()
  File "c:\programdata\anaconda3\lib\site-packages\sqlalchemy\orm\query.py", line 3347, in one
    ret = self.one_or_none()
  File "c:\programdata\anaconda3\lib\site-packages\sqlalchemy\orm\query.py", line 3316, in one_or_none
    ret = list(self)
  File "c:\programdata\anaconda3\lib\site-packages\sqlalchemy\orm\query.py", line 3389, in __iter__
    return self._execute_and_instances(context)
  File "c:\programdata\anaconda3\lib\site-packages\sqlalchemy\orm\query.py", line 3414, in _execute_and_instances
    result = conn.execute(querycontext.statement, self._params)
  File "c:\programdata\anaconda3\lib\site-packages\sqlalchemy\engine\base.py", line 982, in execute
    return meth(self, multiparams, params)
  File "c:\programdata\anaconda3\lib\site-packages\sqlalchemy\sql\elements.py", line 293, in _execute_on_connection
    return connection._execute_clauseelement(self, multiparams, params)
  File "c:\programdata\anaconda3\lib\site-packages\sqlalchemy\engine\base.py", line 1101, in _execute_clauseelement
    distilled_params,
  File "c:\programdata\anaconda3\lib\site-packages\sqlalchemy\engine\base.py", line 1250, in _execute_context
    e, statement, parameters, cursor, context
  File "c:\programdata\anaconda3\lib\site-packages\sqlalchemy\engine\base.py", line 1476, in _handle_dbapi_exception
    util.raise_from_cause(sqlalchemy_exception, exc_info)
  File "c:\programdata\anaconda3\lib\site-packages\sqlalchemy\util\compat.py", line 398, in raise_from_cause
    reraise(type(exception), exception, tb=exc_tb, cause=cause)
  File "c:\programdata\anaconda3\lib\site-packages\sqlalchemy\util\compat.py", line 152, in reraise
    raise value.with_traceback(tb)
  File "c:\programdata\anaconda3\lib\site-packages\sqlalchemy\engine\base.py", line 1246, in _execute_context
    cursor, statement, parameters, context
  File "c:\programdata\anaconda3\lib\site-packages\sqlalchemy\engine\default.py", line 588, in do_execute
    cursor.execute(statement, parameters)
sqlalchemy.exc.OperationalError: (sqlite3.OperationalError) no such table: post_like
[SQL: SELECT count(*) AS count_1 
FROM (SELECT post_like.id AS post_like_id, post_like.user_id AS post_like_user_id, post_like.post_id AS post_like_post_id 
FROM post_like 
WHERE post_like.user_id = ? AND post_like.post_id = ?) AS anon_1]
[parameters: (3, 3)]
(Background on this error at: http://sqlalche.me/e/e3q8)
2020-05-25 15:39:29,205 INFO: Microblog startup [in C:\Users\Администратор\Documents\web_app\app\__init__.py:47]
2020-05-25 15:39:40,224 INFO: Microblog startup [in C:\Users\Администратор\Documents\web_app\app\__init__.py:47]
2020-05-25 15:40:07,030 INFO: Microblog startup [in C:\Users\Администратор\Documents\web_app\app\__init__.py:47]
2020-05-25 15:46:40,390 INFO: Microblog startup [in C:\Users\Администратор\Documents\web_app\app\__init__.py:47]
2020-05-25 15:47:14,544 INFO: Microblog startup [in C:\Users\Администратор\Documents\web_app\app\__init__.py:47]
2020-05-25 15:48:18,370 INFO: Microblog startup [in C:\Users\Администратор\Documents\web_app\app\__init__.py:47]
2020-05-25 15:48:53,042 INFO: Microblog startup [in C:\Users\Администратор\Documents\web_app\app\__init__.py:47]
2020-05-27 01:04:33,262 INFO: Microblog startup [in C:\Users\Администратор\Documents\web_app\app\__init__.py:47]
2020-05-27 12:35:28,777 INFO: Microblog startup [in C:\Users\Администратор\Documents\web_app\app\__init__.py:47]
